Workbook

Sheet 拍摄总表
D1: 订单信息（小拍填）-- 必填 | R1: 定金明细（小拍填） | X1: 渠道市场（小拍填） | AC1: 家人信息（小秘书填） | AN1: 拍摄团队（小秘书填） | AY1: 裂变情况（小秘书填） | BA1: 选片加片（小秘书填） | BF1: 续订情况（小秘书填） | BJ1: 回家另加（小秘书填）
A2: 备注 | B2: 录入人 | C2: 订单编号 | D2: 客户微信名 | E2: 客户姓名 | F2: 手机 | G2: 到店时间 | H2: 拍摄地点 | I2: 套餐名称 | J2: 拍摄对象 | K2: 拍摄内容 | L2: 拍摄时长 | M2: 精修张数 | N2: 未选底片 | O2: 印刷品 | P2: 化妆发型 | Q2: 拍摄心愿 | R2: 定金时间 | S2: 定金金额 | T2: 付款方式 | U2: 套餐金额 | V2: 应付尾款 | W2: 备注 | X2: 介绍人 | Y2: 媒介渠道 | Z2: 参加活动 | AA2: 接单人 | AB2: 类型 | AC2: 大宝姓名 | AD2: 昵称 | AE2: 性别 | AF2: 出生日期 | AG2: 小宝姓名 | AH2: 昵称 | AI2: 性别 | AJ2: 出生日期 | AK2: 其他家人信息 | AL2: 地址 | AM2: 电子邮件 | AN2: 拍摄日期 | AO2: 摄影师 | AP2: 满意度 | AQ2: 化妆师 | AR2: 满意度 | AS2: 引导师/助理 | AT2: 满意度 | AU2: 尾款时间 | AV2: 尾款金额 | AW2: 尾款方式 | AX2: 本单服务金额 | AY2: 是否参加点评活动 | AZ2: 是否发朋友圈 | BA2: 选片人员 | BB2: 付款时间 | BC2: 金额 | BD2: 付款方式 | BE2: 内容 | BF2: 付款时间 | BG2: 续订金额 | BH2: 付款方式 | BI2: 续订内容 | BJ2: 付款时间 | BK2: 金额 | BL2: 付款方式 | BM2: 内容
B3: 丹丹 | C3: S20192001 | D3: 小圆手 | I3: 299台历活动 | S3: 299 | X3: 老客户 | Z3: 台历活动 | AB3: 超低价促销 | AN3: 43454 | AO3: 米加 | AQ3: 无 | AS3: 熊妈 | AU3: / | AV3: 0 | AX3: 299 | BF3: 43456 | BG3: 2880 | BH3: pos | BI3: 2880F
B4: 丹丹 | C4: S20192002 | D4: 咩咩新年照 | Z4: 免费圣诞照 | AB4: 免拍 | AN4: 43463 | AO4: 团子 | AQ4: 明珠 | AS4: 熊妈 | AU4: / | AV4: 0 | AW4: / | AX4: 0
B5: 丹丹 | C5: S20192003 | D5: 两人哺乳照 | AA5: 其他 | AB5: 免拍 | AN5: 43593 | AO5: / | AQ5: / | AS5: / | AU5: / | AV5: / | AW5: / | AX5: / | BF5: 43605 | BG5: 1500 | BH5: pos和支付宝 | BI5: 2880F
B6: 丹丹 | C6: S20192004 | D6: 邓小邓加印刷 | AN6: 43653 | BJ6: 43696 | BK6: 234 | BL6: 支付宝 | BM6: 加印刷
B7: 丹丹 | C7: S20192005 | D7: tinyhands拍摄 | AB7: 其他（活动外拍） | AN7: 43663 | AO7: 立衡/之一 | AQ7: / | AS7: 熊妈 | AU7: 43713 | AV7: 3000 | AW7: 上海银行 | AX7: 3000
B8: 祖祖 | C8: S20192006 | D8: Jihui Zhang | I8: 149证件照 | V8: 134 | AA8: Yuki | AB8: 超低价促销 | AN8: 43806 | AO8: 米加 | AQ8: / | AS8: / | AU8: 43806 | AV8: 134 | AW8: pos | AX8: 134
B9: 祖祖 | C9: S20192007 | D9: CC.JC | I9: 99证件照 | V9: 99 | X9: 老客户 | AA9: Yuki | AB9: 正价 | AN9: 43807 | AO9: 米加 | AQ9: / | AS9: 果冻 | AU9: 43807 | AV9: 99 | AW9: pos | AX9: 99
A10: y | B10: 丹丹 | C10: S20192008 | D10: athena | Z10: ？ | AN10: / | BB10: 43469 | BC10: 240 | BD10: 微信 | BE10: 加精修
B11: 祖祖 | C11: S20192009 | D11: 双 | E11: 吕小姐 | F11: 13816125386 | G11: 未定 | I11: 4480定制 | V11: 4032 | X11: 老客户 | AB11: 正价折扣
B12: 祖祖 | C12: S20192010 | D12: 毛阿毛 | I12: 1080F | X12: 老客户 | AN12: 43827 | AO12: 团子 | AQ12: / | AS12: 小茹/胡清 | AU12: 43827 | AV12: 1080 | AW12: pos | AX12: 1080
B13: 祖祖 | C13: S20192011 | D13: 陆应 | E13: / | F13: 18321718075 | G13: 未定 | H13: 古羊路158号 | I13: 1000职业照 | J13: 个人 | K13: 1套职业照 | L13: 1小时 | M13: 3张 | N13: 不包含 | O13: 不包含 | P13: 包含 | Q13: 多拍几张全身 | R13: 43814 | S13: 500 | T13: 微信 | U13: 1000 | V13: 500 | W13: 朋友推荐 | X13: 张慧 | Z13: 无 | AA13: Yuki | AB13: 正价 | AN13: 43834 | AO13: 立衡
B14: Yuki | C14: S20192012 | D14: Alice | E14: / | F14: 18611970187 | G14: 2020-12月 | H14: Steps四袋拍摄影棚内 | I14: 4480主题定制 | J14: Winston（2017.11.25弟弟）+Wilson（2013.2.7哥哥）+爸爸妈妈 | K14: 宝宝单人照2组，全家福1组 | L14: 2-3小时 | M14: 20 | N14: 全送 | O14: 10寸轻相册一本 | P14: 提供 | Q14: 妈妈拍好看，单人照哥哥和弟弟各一组。 | R14: 43814 | S14: 2000 | T14: 支付宝500+现金1500 | U14: 4480 | V14: 2480 | W14: 老客户续约，拍摄时间暂定12月左右，提前一个月确认具体时间 | X14: 老客户 | Y14: 续订 | AA14: Yuki | AB14: 正价
A15: 已打印 | B15: Yuki | C15: S20192013 | D15: yanghx | E15: 杨女士 | F15: 13774245131 | G15: 2020.1.1 10:00:00 | H15: Steps四袋拍摄影棚内 | I15: 3680亲子+儿童 | J15: 可可（2019.1.12妹妹）+哥哥+爸爸妈妈 | K15: 宝宝单人照1组，全家福1组 | L15: 2-3小时 | M15: 18 | N15: 全送 | O15: 8寸萝莉册 | P15: 提供 | Q15: 套餐先待定3680，沟通过风格后可更换其他套餐 | R15: 43815 | S15: 500 | T15: 微信 | U15: 3680 | V15: 3180 | W15: 全家福哥哥免费出镜，另外再拍点哥哥和妹妹的合影 | Y15: 点评 | AA15: Yuki | AB15: 正价 | AN15: 43831 | AO15: 米加 | AQ15: 10 | AS15: 陈晓 | AU15: 43831 | AV15: 3180 | AW15: pos | AX15: 3680
B16: Yuki | C16: S20192014 | D16: ultraman | E16: 韩晓晨 | F16: 13701920221 | G16: 2020.3月-2021.3月 | H16: Steps四袋拍摄影棚内 | I16: 2980儿童肖像 | J16: 小太阳（2019.3.22男孩） | K16: 宝宝单人照2组 | L16: 2小时左右 | M16: 16 | N16: 全送 | O16: 20寸油画框 | P16: 提供 | Q16: 套餐可转闺蜜照，如果闺蜜照只拍1组价格可按照2980个人self的基础上额外增加500/人，另外多2张精修的费用算，如果拍宝宝单人照或者全家福可在2年左右拍完。 | R16: 43815 | S16: 2480 | T16: pos | U16: 2480 | V16: 0 | W16: 老客户续约，套餐暂定2480，后期可更换其他正价套餐。 | X16: 御姐萌妹 | Y16: 续订 | AA16: Yuki | AB16: 平日特惠
B17: Yuki | C17: S20192015 | D17: mich | E17: 朱一菡 | F17: 13632223176 | G17: 2020.9月左右 | H17: Steps四袋拍摄影棚内 | I17: 2880全家福 | J17: 弟弟（2019.9.3）+暖暖（2015.12.23姐姐）+爸爸妈妈 | K17: 棚内家庭照1组 | L17: 2小时左右 | M17: 12 | N17: 全送 | O17: 20寸油画框 | P17: 提供 | Q17: 弟弟单人照和姐姐单人照都拍一点 | R17: 43815 | S17: 2880 | T17: pos | U17: 2880 | V17: 0 | W17: 老客户续约，拍摄时间暂定弟弟9月生日前后。 | X17: 老客户 | Y17: 续订 | AA17: Yuki | AB17: 正价
A18: 已打印 | B18: Yuki | C18: S20192016 | D18: 团子 | E18: 葛晓滢 | F18: 13524455895 | G18: 2020.12.22.10：00 | H18: Steps四袋拍摄影棚内 | I18: 4480主题定制 | J18: 兜兜（2019.9.10男孩）+爸爸妈妈+外公外婆 | K18: 宝宝单人照2组，全家福1组 | L18: 2-3小时左右 | M18: 20+4=24张 | N18: 全送 | O18: 10寸轻相册一本 | P18: 提供 | Q18: 棚内有适合兜兜的服装可提供 | R18: 43817 | S18: 500 | T18: 微信 | U18: 4480 | V18: 3980 | W18: 一家三口 | Y18: 点评 | AA18: Yuki | AB18: 正价 | AN18: 43821 | AO18: 米加 | AQ18: 10 | AS18: 果冻/胡清 | AU18: 43821 | AV18: 3980 | AW18: pos | AX18: 4480 | BF18: 43825 | BG18: 1500 | BH18: pos | BI18: 2980儿童肖像
A19: 已打印 | B19: Yuki | C19: S20192017 | D19: hengyi | E19: 18916171988 | F19: 赵恒谊 | G19: 2020.1.11.16：30 | H19: Steps四袋拍摄影棚内 | I19: 5900steps3 | J19: 安康（2019.1.16男孩）+爸爸妈妈+爷爷奶奶 | K19: 棚内2套 | L19: 2-3小时左右 | M19: 15+2=17张 | N19: 全送 | O19: 20寸油画框 | P19: 提供 | Q19: / | R19: / | S19: / | T19: / | U19: 5900steps | V19: 500 | W19: 成长套餐最后一次拍摄。 | X19: 老客户 | AA19: Yuki | AB19: 正价 | AD19: 安康 | AE19: 男 | AF19: 43481
A20: 已打印 | B20: Yuki | C20: S20192018 | D20: 蛋黄小噗噗 | E20: 吴佳琳 | F20: 15026768701 | G20: 43871.417 | H20: Steps四袋拍摄影棚内 | I20: 4480主题定制 | J20: 齐齐（2019.2月男孩）+爸爸妈妈 | K20: 宝宝单人照2组，全家福1组，哺乳照1组。 | L20: 2-3小时左右 | M20: 20+2=22张 | N20: 全送 | O20: 10寸轻相册一本 | P20: 包含 | Q20: 要拍一点抓周照。 | R20: 43817 | S20: 3680 | T20: 点评 | U20: 3680平日特惠 | V20: 0 | W20: 老客户续约，平日拍摄活动折后3680，另外拍1组哺乳照。 | X20: 老客户 | Y20: 续订 | AA20: Yuki | AB20: 正价折扣
B21: Yuki | C21: S20192019 | D21: Karen niu | E21: 牛佳 | F21: 13918116199 | G21: 2020-12月左右 | H21: 黄金城道/新虹桥中心花园 | I21: 1980mini外景 | J21: 11（2012.11.9姐姐）+22（2017.7.7妹妹）+爸爸妈妈 | K21: 家庭照 | L21: 50分钟 | M21: 10 | N21: 全送 | O21: 无 | P21: 自备 | Q21: 可带长辈出镜 | R21: 43817 | S21: 1980 | T21: pos | U21: 1980 | V21: 0 | W21: 老客户续约，拍摄黄金雨或者新虹桥中心花园待定，提前一个月确认。 | X21: 老客户 | Y21: 续订 | AA21: Yuki | AB21: 正价
A22: 已打印 | B22: Yuki | C22: S20192020 | D22: 奶牛宝宝 | E22: 万丽 | F22: 13501720358 | G22: 43826.667 | H22: Steps四袋拍摄影棚内 | I22: 2980全家福+光影 | J22: Mario（2015.4.26弟弟）+姐姐（2013.06.19）+爸爸妈妈 | K22: 家庭照 | L22: 2个小时左右 | M22: 12+1 | N22: 全送 | O22: 20寸油画框 | P22: 提供 | Q22: 全家福风格正常沟通，另外可再拍一组剪影照或者表情包，现场确认。 | R22: 43817 | S22: 500 | T22: 微信 | U22: 2980 | V22: 2480 | W22: 老客户续拍，免费多一人入镜。 | X22: 老客户 | AA22: Yuki | AB22: 正价折扣 | AN22: 43827 | AO22: 立衡 | AQ22: 王婵 | AS22: 果冻/小茹 | AU22: 43827 | AV22: 2480 | AW22: pos | AX22: 2980
A23: 已打印 | B23: Yuki | C23: S20192021 | D23: Richie | E23: 陈周平 | F23: 13816067670 | G23: 43825.562 | H23: Steps四袋拍摄影棚内 | I23: 4480主题定制 | J23: 陈不染（2019.9.15女孩）+爸爸妈妈 | K23: 宝宝单人照2组，全家福1组，哺乳照1组。 | L23: 2-3小时左右 | M23: 20+2=22 | N23: 全送 | O23: 10寸轻相册一本 | P23: 提供 | Q23: 待沟通 | R23: 43818 | S23: 3680 | T23: 点评 | U23: 3680 | V23: 0 | W23: 点评活动，平日拍折后3680。 | Y23: 点评 | AA23: Yuki | AB23: 正价折扣 | AN23: 43825 | AO23: 米加 | AQ23: 10 | AS23: 果冻 | AU23: / | AV23: / | AW23: / | AX23: 3680
B24: Yuki | C24: S20192022 | D24: 不懒了 | E24: 蓝天皓 | F24: 13801951105 | G24: 2020-2月下旬 | H24: Steps四袋拍摄影棚内 | I24: 4480主题定制 | J24: 菜菜（2015.11.28姐姐）+肉肉（2019.11.9妹妹）+爸爸妈妈 | K24: 宝宝单人照2组，全家福1组，哺乳照1组。 | L24: 2-3小时左右 | M24: 20+2=22 | N24: 全送 | O24: 10寸轻相册一本 | P24: 提供 | Q24: 单人照可姐姐妹妹各一组。 | R24: 43818 | S24: 3680 | T24: 点评 | U24: 3680 | V24: 0 | W24: 老客户续拍，平日拍摄套餐折后3680，百日大概2.27号左右，时间暂定百日，最晚周岁前拍摄完成 | X24: 老客户 | Y24: 续订 | AA24: Yuki | AB24: 正价折扣
A25: 已打印 | B25: Yuki | C25: S20192023 | D25: 一蒙 | E25: / | F25: 18117102052 | G25: 44193.417 | H25: Steps四袋拍摄影棚内 | I25: 4880全家福 | J25: 又欢（2014.3.16姐姐）+又乐（2017.1月妹妹）+爸爸妈妈 | K25: 棚内2套 | L25: 2-3小时左右 | M25: 25 | N25: 全送 | O25: 10寸轻相册一本 | P25: 提供 | Q25: 待沟通 | R25: / | S25: 500 | T25: 微信 | U25: 3848 | V25: 3348 | W25: 参加转发活动套系-300，老客户预约新套餐套系85折 | X25: 老客户 | AA25: Yuki | AB25: 正价折扣
B26: Yuki | C26: S20192024 | D26: 阿池池 | E26: 池小姐 | F26: 13918210550 | G26: 2020-11-12月左右 | H26: Steps四袋拍摄影棚内 | I26: 3980外景 | J26: 球球（2016.11.10男孩）+爸爸妈妈 | K26: 家庭照 | L26: 2小时 | M26: 20张 | N26: 全送 | O26: 10寸轻相册一本 20寸油画框一个 | P26: 提供 | Q26: 待沟通 | R26: 43818 | S26: 3580 | T26: 点评 | U26: 3580 | V26: 0 | W26: 老客户续拍，点评活动折后3580。拍摄时间暂定12月左右，提前一个月左右确认时间。拍黄金雨。 | X26: 老客户 | Y26: 续订 | AA26: Yuki | AB26: 正价折扣
A27: 已打印 | B27: Yuki | C27: S20192025 | D27: 周咩咩 | E27: 陆海源 | F27: 18516089280 | G27: 43819.417 | H27: Steps四袋拍摄影棚内 | I27: 1400小主题 | J27: Ollie | K27: 棚内1套宝宝单人 | L27: 1小时左右 | M27: 8 | N27: 不含 | O27: 7寸精致摆台 一个 | P27: 提供 | Q27: 待沟通 | R27: 43818 | S27: 1400 | T27: 微信 | U27: 1400 | V27: 0 | W27: 老客户续拍额外赠送一个摆台。 | X27: 老客户 | AA27: Yuki | AB27: 超低价促销 | AN27: 43819 | AO27: 立衡 | AQ27: 10 | AS27: 果冻 | AU27: / | AV27: / | AW27: / | AX27: 1400 | BF27: 43819 | BG27: 1400
A28: 已打印 | B28: Yuki | C28: S20192026 | D28: 金钥匙 | E28: 曹晓 | F28: 18001783093 | G28: 43820.667 | H28: Steps四袋拍摄影棚内 | I28: 1400小主题 | J28: 兴宝（2013.8.25男孩)+妈妈 | K28: 棚内1套 | L28: 1小时左右 | M28: 8+2=10 | N28: 全送 | O28: 无 | P28: 提供 | Q28: 待沟通 | R28: 43818 | S28: 500 | T28: 微信 | U28: 1400+500=1900 | V28: 1400 | W28: 另外增加妈妈入镜，额外增加500，多2张精修。 | X28: 之一 | AA28: Yuki | AB28: 超低价促销 | AN28: 43820 | AO28: 米加 | AQ28: 10 | AS28: 果冻/小茹 | AU28: 43820 | AV28: 1400 | AW28: pos | AX28: 1900
A29: 已打印 | B29: Yuki | C29: S20192027 | D29: 周公子（danny） | E29: danny | F29: 15800510390 | G29: 43841.417 | H29: Steps四袋拍摄影棚内 | I29: 2880全家福 | J29: 果果（2016.12.06男孩）+妈妈+外公外婆 | K29: 棚内1套 | L29: 2小时左右 | M29: 12 | N29: 全送 | O29: 20寸油画框一个 | P29: 提供 | Q29: 待沟通 | R29: 43819 | S29: 500 | T29: 微信 | U29: 3000 | V29: 2500 | W29: 额外增加一位长辈出镜，增加120，仅限此单。 | X29: / | AA29: Yuki | AB29: 正价
B30: Yuki | C30: S20192028 | D30: 周咩咩 | E30: 陆海源 | F30: 18516089280 | G30: 2020-4月 | H30: Steps四袋拍摄影棚内 | I30: 2980儿童肖像 | J30: Ollie（2016.4.12女孩） | K30: 棚内2套 | L30: 2小时左右 | M30: 16 | N30: 全送 | O30: 20寸油画框一个 | P30: 提供 | Q30: 一套拍油画风，另外一套待定。 | R30: 43819 | S30: 1400 | T30: 微信 | U30: 2480 | V30: 1080 | W30: 平日拍套餐-500，折后2480，拍摄时间4月具体待定。 | X30: 老客户 | Y30: 续订 | AA30: Yuki | AB30: 正价折扣
A31: 已打印 | B31: Yuki | C31: S20192029 | D31: 袁佳 | E31: 袁佳 | F31: 18601702120 | G31: 43821.417 | H31: Steps四袋拍摄影棚内 | I31: 3580孕照 | J31: 袁佳（预产期2月初）+准爸爸 | K31: 棚内2套 | L31: 2-3小时左右 | N31: 全送 | O31: 21寸油画框一个 | P31: 提供 | Q31: 待沟通 | R31: 43819 | S31: 500 | T31: 微信 | U31: 3580 | V31: 3080 | W31: / | X31: / | Y31: 点评 | AA31: Yuki | AB31: 正价 | AN31: 43821 | AO31: 立衡 | AQ31: summer | AS31: 熊妈 | AU31: 43821 | AV31: 3080 | AW31: pos | AX31: 3580 | BF31: 43826 | BG31: 3300
A32: 已打印 | B32: Yuki | C32: S20192030 | D32: 橙非比 Phoebe | E32: 程序 | F32: 13661662466 | G32: 43825.417 | H32: Steps四袋拍摄影棚内 | I32: 2980全家福+光影 | J32: 米多多（2014.9月女孩）+爸爸妈妈+外公外婆 | K32: 全家福1组，光影/表情包1组。 | L32: 2小时左右 | M32: 12+1+4=17张 | N32: 全送 | O32: 20寸油画框一个 | P32: 提供 | Q32: 想拍油画风 | R32: 43819 | S32: 2980 | T32: 点评 | U32: 3980 | V32: 1000 | W32: 额外增加外公外婆出镜，多1000出镜费用，多4张精修。 | X32: / | AA32: Yuki | AB32: 正价折扣
A33: 已打印 | B33: Yuki | C33: S20192031 | D33: 栗子 | E33: 刘玮玮 | F33: 13564339618 | G33: 43834.562 | H33: Steps四袋拍摄影棚内 | I33: 2880全家福 | J33: 窈窈（201512女孩）+爸爸妈妈 | K33: 棚内1套 | L33: 2小时左右 | M33: 12+3=15 | N33: 全送 | O33: 绒面桌摆 | P33: 提供 | Q33: 待沟通 | R33: 43819 | S33: 500 | T33: / | U33: 2880 | V33: 2380 | W33: 拍摄1组，团子推荐额外赠送一个绒面小桌摆，原套餐相框不要换3张精修。 | X33: / | AA33: Yuki | AB33: 正价
A34: 已打印 | B34: Yuki | C34: S20192032 | D34: KoKi | E34: 胡琪 | F34: 15618012875 | G34: 43821.562 | H34: Steps四袋拍摄影棚内 | I34: 2980儿童肖像 | J34: Lucas（2015.1.27男孩）+爸爸妈妈 | K34: 全家福1组，光影 | L34: 2小时左右 | M34: 12+1=13 | N34: 全送 | O34: 20寸油画框一个 | P34: 提供 | Q34: 待沟通 | R34: 43821 | S34: 2980 | T34: 点评 | U34: 2980 | V34: 0 | W34: 点评活动，平日拍2980，特殊安排周末。 | X34: 点评 | AA34: Yuki | AB34: 正价折扣 | AN34: 43821 | AO34: 立衡 | AQ34: 胡悠 | AS34: 熊妈 | AU34: / | AV34: / | AW34: / | AX34: 2980
B35: Yuki | C35: S20192033 | D35: 罗斯玛丽朱小妹 | E35: / | F35: 18018667505 | G35: 2020-4-5月 | H35: Steps四袋拍摄影棚内 | I35: 待定 | J35: 晞晞（2012.3.3姐姐）+翰翰（2018.1.30弟弟）+待定 | K35: 待定 | L35: 待定 | M35: 待定 | N35: 待定 | O35: 待定 | P35: 提供 | Q35: 待沟通 | R35: 43821 | S35: 500 | T35: / | U35: 待定 | V35: / | W35: 圣诞照续约，预付500定金，套餐待定，提前微信确认。 | X35: 老客户 | AA35: Yuki
A36: 已打印 | B36: Yuki | C36: S20192034 | D36: 朱婧 | E36: / | F36: 15221391157 | G36: 43834.396 | H36: Steps四袋拍摄影棚内 | I36: 4990每年全家福 | J36: 祎祎（2017.1.11女孩）+爸爸妈妈 | K36: 棚内2套 | L36: 2-3小时左右 | M36: 14 | N36: 全送 | O36: 20寸油画框一个 | P36: 提供 | Q36: 待沟通 | R36: / | S36: / | T36: / | U36: / | V36: / | W36: 成长套餐第二次 | X36: 老客户 | AA36: Yuki | AB36: 正价 | AD36: 祎祎 | AE36: 女 | AF36: 42746
A37: 已打印 | B37: Yuki | C37: S20192035 | D37: 高书恒 | E37: 高书恒 | F37: 15370119812 | G37: 43848.417 | H37: Steps四袋拍摄影棚内 | I37: 2020新年照 | J37: 阳阳（2015.09.11哥哥）+沐沐（2018.04.04弟弟）+爸爸妈妈 | K37: 棚内1套 | L37: 2小时左右 | M37: 6+2=8 | N37: 无 | O37: 7寸精致摆台 一个 | P37: 提供 | Q37: 拍新年照，哥哥120弟弟90，80/110也可以穿 | R37: 43821 | S37: 500 | T37: 微信 | U37: 2020+500=2520 | V37: 2020 | W37: / | AA37: Yuki | AB37: 超低价促销
B38: Yuki | C38: S20192036 | D38: 胖雪闹闹 | E38: 吴姝丽 | F38: 15902145929 | G38: 2020-12月 | H38: Steps四袋拍摄影棚内 | I38: 2880F | J38: 晓晓（2018.12.11女孩）+爸爸妈妈 | K38: 棚内1套 | L38: 2小时左右 | M38: 12 | N38: 全送 | O38: 20寸油画框一个 | P38: 提供 | Q38: 待沟通 | R38: 43821 | S38: 2880 | T38: POS | U38: 2880 | V38: 0 | W38: 周岁照续约，套餐暂定2880，提前一个月确定拍摄时间和套餐，风格待定。 | X38: 老客户 | Y38: 续订 | AA38: Yuki | AB38: 正价
A39: 已打印 | B39: Yuki | C39: S20192037 | D39: 茗芳 | E39: 单女士 | F39: 13524497723 | G39: 43827.667 | H39: Steps四袋拍摄影棚内 | I39: 2020新年照 | J39: 蟠蟠2012.12.6男孩）+爸爸妈妈 | K39: 棚内1套 | L39: 2小时左右 | M39: 6+2=8 | N39: 无 | O39: 7寸精致摆台 一个 | P39: 提供 | Q39: 待沟通 | R39: 43822 | S39: 500 | T39: 微信 | U39: 2020 | V39: 1520 | W39: 之一同学妈妈推荐，额外多送2张精修。 | X39: 金钥匙 | AA39: Yuki | AB39: 超低价促销 | AN39: 43827 | AO39: 米加 | AQ39: 10 | AS39: 小茹/阿哲 | AU39: 43827 | AV39: 1520 | AW39: pos | AX39: 2020
A40: 已打印 | B40: Yuki | C40: S20192038 | D40: 尤嘉 | E40: 尤嘉 | F40: 19822798256 | G40: 43825.417 | H40: Steps四袋拍摄影棚内 | I40: 8880成长2次 | J40: 钖钖（2015.7.13哥哥）+阿端（2016.4.1弟弟） | K40: 棚内2套 | L40: 2-3小时左右 | M40: 25 | N40: 全送 | O40: 10寸轻相册一本 40寸相框 一个 | P40: 提供 | Q40: 待沟通 | R40: / | S40: / | T40: / | U40: 8000 | V40: 0 | W40: 产品相框要不要做选照片时确认，成长第一次。 | X40: 老客户 | AA40: Yuki | AB40: 正价 | AN40: 43825 | AO40: 团子 | AQ40: 10 | AS40: 果冻/熊妈 | AU40: / | AV40: / | AW40: / | AX40: 4000
...

Sheet 棚内
B2: 拍摄确认单 | J2: 订单编号 | K2: S20192075
B4: 客户微信名 | D4: =VLOOKUP(K2,拍摄总表!C:Q,2,0) -> 惠慧Amy（DG） | E4: =VLOOKUP(K2,拍摄总表!C:Q,3,0) -> 惠慧 | F4: 手机号 | G4: =VLOOKUP(K2,拍摄总表!C:Q,4,0) -> 13040626829 | J4: 介绍人 | K4: =VLOOKUP(K2,拍摄总表!C:AB,22,0) -> Carrie
B5: 到店时间 | D5: =VLOOKUP(K2,拍摄总表!C:Q,5,0) -> 43834.396 | F5: 拍摄地点 | G5: =VLOOKUP(K2,拍摄总表!C:Q,6,0) -> Steps四袋拍摄影棚内 | J5: 参加活动 | K5: =VLOOKUP(K2,拍摄总表!C:AB,24,0) -> 0
B7: 套餐名称 | D7: =VLOOKUP(K2,拍摄总表!C:Q,7,0) -> 6980平日大全家福 | J7: 摄影师
B8: 拍摄对象 | D8: =VLOOKUP(K2,拍摄总表!C:Q,8,0) -> 俞嘉浩（2004.08.26男生）+Yu Kawo（2010，9.25男生）+爸爸妈妈_x000D_孙文琦（2003.1.22女生）+孙可可（2014.08.26女生）+爸爸妈妈+两位长辈 | J8: 引导/助理
B9: 拍摄内容 | D9: =VLOOKUP(K2,拍摄总表!C:Q,9,0) -> 棚内2组 | J9: 化妆师
B10: 拍摄时长 | D10: =VLOOKUP(K2,拍摄总表!C:Q,10,0) -> 3-4小时
B11: 精修张数 | D11: =VLOOKUP(K2,拍摄总表!C:Q,11,0) -> 38
B12: 未选底片 | D12: =VLOOKUP(K2,拍摄总表!C:Q,12,0) -> 全送
B13: 印刷品 | D13: =VLOOKUP(K2,拍摄总表!C:Q,13,0) -> 10寸轻相册 一本 _x000D_24寸油画框 一个_x000D_10寸精致摆台 一个
B14: 化妆发型 | D14: =VLOOKUP(K2,拍摄总表!C:Q,14,0) -> 提供
B15: 拍摄心愿 | D15: =VLOOKUP(K2,拍摄总表!C:Q,15,0) -> 待沟通
B17: 总金额（元） | D17: =VLOOKUP(K2,拍摄总表!C:AB,19,0) -> 6980 | F17: 尾款（元） | G17: =VLOOKUP(K2,拍摄总表!C:AB,20,0) -> 6480 | H17: （需在拍摄当天付清） | J17: 另加费用
B18: 备注 | D18: =VLOOKUP(K2,拍摄总表!C:AB,21,0) -> 点评活动平日特惠6980
B20: * 关于改期 | D20: 改期费300元（提前7天以上不收改期费）。每一场拍摄团队只服务一组客人，请勿随意改期哦。 | J20: 实收尾款
B21: * 加家人拍摄 | D21: 500元/位，包含妆发，多2张精修
B22: * 加背景及服装 | D22: 1400元/组，精修多6张 | J22: 付款日期
B23: * 另加精修 | D23: 100元/张
B24: * 何时选片 | D24: 拍摄完一周左右 | J24: 付款方式
B25: * 修片&印刷周期 | D25: 修片20天，印刷2周
F26: 客户确认签字
B30: 选片日期 | F30: 选片人 | J30: 选片另加费用
B32: 精修张数 | D32: 张（是否参加点评： 是 / 否 ） | F32: 未修底片 | H32: 张
O33: z
B34: 印刷品 | D34: （颜色、款式、尺寸、照片序号）
B36: 修片要求 | J36: 付款日期
J38: 付款方式
B39: 注： | D39: 由于相框为易碎品，为避免意外，如需发快递只发本市，且24寸以上相框需到店自取。
F40: 客户确认签字

Sheet 哺乳照
B2: 拍摄确认单 | J2: 订单编号 | K2: S20192062
B4: 客户微信名 | D4: =VLOOKUP(K2,拍摄总表!C:Q,2,0) -> nicongai | E4: =VLOOKUP(K2,拍摄总表!C:Q,3,0) -> 倪雯娇 | F4: 手机号 | G4: =VLOOKUP(K2,拍摄总表!C:Q,4,0) -> 13918852376 | J4: 介绍人 | K4: =VLOOKUP(K2,拍摄总表!C:AB,22,0) -> 点评
B5: 到店时间 | D5: =VLOOKUP(K2,拍摄总表!C:Q,5,0) -> 43828.562 | F5: 拍摄地点 | G5: =VLOOKUP(K2,拍摄总表!C:Q,6,0) -> Steps四袋拍摄影棚内 | J5: 参加活动 | K5: =VLOOKUP(K2,拍摄总表!C:AB,24,0) -> 0
B7: 套餐名称 | D7: =VLOOKUP(K2,拍摄总表!C:Q,7,0) -> 880哺乳照 | J7: 摄影师
B8: 拍摄对象 | D8: =VLOOKUP(K2,拍摄总表!C:Q,8,0) -> 一克拉（2019.4月女孩）+妈妈 | J8: 引导/助理
B9: 拍摄内容 | D9: =VLOOKUP(K2,拍摄总表!C:Q,9,0) -> 棚内1套 | J9: 化妆师
B10: 拍摄时长 | D10: =VLOOKUP(K2,拍摄总表!C:Q,10,0) -> 1-2小时左右
B11: 精修张数 | D11: =VLOOKUP(K2,拍摄总表!C:Q,11,0) -> 1
B12: 未选底片 | D12: =VLOOKUP(K2,拍摄总表!C:Q,12,0) -> 无
B13: 印刷品 | D13: =VLOOKUP(K2,拍摄总表!C:Q,13,0) -> 无
B14: 化妆发型 | D14: =VLOOKUP(K2,拍摄总表!C:Q,14,0) -> 提供
B15: 拍摄心愿 | D15: =VLOOKUP(K2,拍摄总表!C:Q,15,0) -> 待沟通
B17: 总金额（元） | D17: =VLOOKUP(K2,拍摄总表!C:AB,19,0) -> 880 | F17: 尾款（元） | G17: =VLOOKUP(K2,拍摄总表!C:AB,20,0) -> 380 | H17: （需在拍摄当天付清） | J17: 另加费用
B18: 备注 | D18: =VLOOKUP(K2,拍摄总表!C:AB,21,0) -> 先约880，拍摄完确定要不要更换套餐。
B20: * 关于改期 | D20: 改期费300元（提前7天以上不收改期费）。每一场拍摄团队只服务一组客人，请勿随意改期哦。 | J20: 实收尾款
B21: * 加家人拍摄 | D21: 500元/位，包含妆发，多2张精修
B22: * 加背景及服装 | D22: 1400元/组，精修多6张 | J22: 付款日期
B23: * 另加精修 | D23: 200元/张
B24: * 何时选片 | D24: 拍摄完一周左右 | J24: 付款方式
B25: * 修片&印刷周期 | D25: 修片1周，印刷2周
F27: 客户确认签字
B31: 选片日期 | F31: 选片人 | J31: 选片另加费用
B33: 精修张数 | D33: 张（是否参加点评： 是 / 否 ） | F33: 未修底片 | H33: 张
O34: z
B35: 印刷品 | D35: （颜色、款式、尺寸、照片序号）
B37: 修片要求 | J37: 付款日期
J39: 付款方式
B40: 注： | D40: 由于相框为易碎品，为避免意外，如需发快递只发本市，且24寸以上相框需到店自取。
F41: 客户确认签字

Sheet 职业照
B2: 拍摄确认单 | J2: 订单编号 | K2: S20192068
B4: 客户微信名 | D4: =VLOOKUP(K2,拍摄总表!C:Q,2,0) -> 雷蒙德 | E4: =VLOOKUP(K2,拍摄总表!C:Q,3,0) -> 李衡 | F4: 手机号 | G4: =VLOOKUP(K2,拍摄总表!C:Q,4,0) -> 18621507331 | J4: 介绍人 | K4: =VLOOKUP(K2,拍摄总表!C:AB,22,0) -> 保时捷
B5: 到店时间 | D5: =VLOOKUP(K2,拍摄总表!C:Q,5,0) -> 43833.562 | F5: 拍摄地点 | G5: =VLOOKUP(K2,拍摄总表!C:Q,6,0) -> Steps四袋拍摄影棚内 | J5: 参加活动 | K5: =VLOOKUP(K2,拍摄总表!C:AB,24,0) -> 0
B7: 套餐名称 | D7: =VLOOKUP(K2,拍摄总表!C:Q,7,0) -> 1000元职业照 | J7: 摄影师
B8: 拍摄对象 | D8: =VLOOKUP(K2,拍摄总表!C:Q,8,0) -> 李衡 | J8: 引导/助理
B9: 拍摄内容 | D9: =VLOOKUP(K2,拍摄总表!C:Q,9,0) -> 棚内1套 | J9: 化妆师
B10: 拍摄时长 | D10: =VLOOKUP(K2,拍摄总表!C:Q,10,0) -> 1-2小时左右
B11: 精修张数 | D11: =VLOOKUP(K2,拍摄总表!C:Q,11,0) -> 3
B12: 未选底片 | D12: =VLOOKUP(K2,拍摄总表!C:Q,12,0) -> 无
B13: 印刷品 | D13: =VLOOKUP(K2,拍摄总表!C:Q,13,0) -> 无
B14: 化妆发型 | D14: =VLOOKUP(K2,拍摄总表!C:Q,14,0) -> 提供
B15: 拍摄心愿 | D15: =VLOOKUP(K2,拍摄总表!C:Q,15,0) -> 待沟通
B17: 总金额（元） | D17: =VLOOKUP(K2,拍摄总表!C:AB,19,0) -> / | F17: 尾款（元） | G17: =VLOOKUP(K2,拍摄总表!C:AB,20,0) -> / | H17: （需在拍摄当天付清） | J17: 另加费用
B18: 备注 | D18: =VLOOKUP(K2,拍摄总表!C:AB,21,0) -> 保时捷员工拍摄券，费用已付。
B20: * 关于改期 | D20: 改期费300元（提前7天以上不收改期费）。每一场拍摄团队只服务一组客人，请勿随意改期哦。 | J20: 实收尾款
B21: * 加团队合影 | D21: 加成员，480元/位，多1张精修。合影精修价格=人数*100元/张
B22: * 加背景及服装 | D22: 1000元/组，精修多3张 | J22: 付款日期
B23: * 另加精修 | D23: 300元/张
B24: * 何时选片 | D24: 拍摄完一周 or 当场选片 | J24: 付款方式
B25: * 修片周期 | D25: 单人套餐：1周；多人团队：20天
F27: 客户确认签字
B31: 选片日期 | F31: 选片人 | J31: 选片另加费用
B33: 精修张数 | D33: 张 | F33: 未修底片 | H33: 张
O34: z
B35: 印刷品 | D35: （颜色、款式、尺寸、照片序号）
B37: 修片要求 | J37: 付款日期
J39: 付款方式
B40: 注： | D40: 由于相框为易碎品，为避免意外，如需发快递只发本市，且24寸以上相框需到店自取。
F41: 客户确认签字

Sheet 外景
B2: 外景 拍摄确认单 | J2: 订单编号
B4: 客户微信名 | D4: =VLOOKUP(K2,拍摄总表!C:Q,2,0) -> #N/A | E4: =VLOOKUP(K2,拍摄总表!C:Q,3,0) -> #N/A | F4: 手机号 | G4: =VLOOKUP(K2,拍摄总表!C:Q,4,0) -> #N/A | J4: 介绍人 | K4: =VLOOKUP(K2,拍摄总表!C:AB,22,0) -> #N/A
B5: 到店时间 | D5: =VLOOKUP(K2,拍摄总表!C:Q,5,0) -> #N/A | F5: 拍摄地点 | G5: =VLOOKUP(K2,拍摄总表!C:Q,6,0) -> #N/A | J5: 参加活动 | K5: =VLOOKUP(K2,拍摄总表!C:AB,24,0) -> #N/A
B7: 套餐名称 | D7: =VLOOKUP(K2,拍摄总表!C:Q,7,0) -> #N/A | J7: 摄影师
B8: 拍摄对象 | D8: =VLOOKUP(K2,拍摄总表!C:Q,8,0) -> #N/A | J8: 引导/助理
B9: 拍摄内容 | D9: =VLOOKUP(K2,拍摄总表!C:Q,9,0) -> #N/A | J9: 化妆师
B10: 拍摄时长 | D10: =VLOOKUP(K2,拍摄总表!C:Q,10,0) -> #N/A
B11: 精修张数 | D11: =VLOOKUP(K2,拍摄总表!C:Q,11,0) -> #N/A
B12: 未选底片 | D12: =VLOOKUP(K2,拍摄总表!C:Q,12,0) -> #N/A
B13: 印刷品 | D13: =VLOOKUP(K2,拍摄总表!C:Q,13,0) -> #N/A
B14: 化妆发型 | D14: =VLOOKUP(K2,拍摄总表!C:Q,14,0) -> #N/A
B15: 拍摄心愿 | D15: =VLOOKUP(K2,拍摄总表!C:Q,15,0) -> #N/A
B17: 总金额（元） | D17: =VLOOKUP(K2,拍摄总表!C:AB,19,0) -> #N/A | F17: 尾款（元） | G17: =VLOOKUP(K2,拍摄总表!C:AB,20,0) -> #N/A | H17: （需在拍摄当天付清） | J17: 另加费用
B18: 备注 | D18: =VLOOKUP(K2,拍摄总表!C:AB,21,0) -> #N/A
B20: * 关于改期 | D20: 改期费300元（提前7天以上不收改期费）。每一场拍摄团队只服务一组客人，请勿随意改期哦。如遇天气不佳，可免费另约拍摄时间，或视情况改拍棚内套餐。 | J20: 实收尾款
B21: * 加家庭拍摄 | D21: 800元/家庭，多3张精修
B22: * 加拍时长 | D22: 1000元/小时 | J22: 付款日期
B23: * 另加化妆 | D23: 500元/小家庭3人 | F23: * 另加长辈化妆 | H23: 200元/人
B24: * 另加精修 | D24: 100元/张 | F24: * 何时选片 | H24: 拍摄完一周左右 | J24: 付款方式
F26: 客户确认签字
B30: 选片日期 | F30: 选片人 | J30: 选片另加费用
B32: 精修张数 | D32: 张（是否参加点评： 是 / 否 ） | F32: 未修底片 | H32: 张
O33: z
B34: 印刷品 | D34: （颜色、款式、尺寸、照片序号）
B36: 修片要求 | J36: 付款日期
J38: 付款方式
B39: 注： | D39: 由于相框为易碎品，为避免意外，如需发快递只发本市，且24寸以上相框需到店自取。
F40: 客户确认签字

Sheet 所有套餐列表
A1: 2880全家福
A2: 3980全家福
A3: 4480主题定制
A4: 2980个人肖像
A5: 4280个人肖像
A6: 3580闺蜜照
A7: 4880大家庭
A8: 7580大家庭
A9: 婚纱肖像
A10: 3580孕照
A11: 2980儿童肖像
A12: 2480儿童平日
... A38: 其他
